Workbook

Sheet Cover
A1: MICROSOFT CORPORATION (NASDAQ: MSFT)
A2: Independent Equity Research & Valuation Model
A3: Valuation reference date: October 27, 2026
A5: MODEL OVERVIEW | E5: MODEL SCOPE
A6: Company | B6: Microsoft Corporation (NASDAQ: MSFT) | E6: Integrated financial statements
A7: Author | B7: Eden Kabanga | E7: Bear / Base / Bull scenarios
A8: Research period | B8: FY2022–FY2026 historical analysis | E8: DCF and valuation sensitivities
A9: Projection period | B9: FY2027–FY2031 explicit projections; FY2032–FY2036 DCF normalization | E9: Historical peer P/E cross-check
A10: Research focus | B10: Can Microsoft's AI investment generate sufficient returns to justify current capital intensity? | E10: WACC, beta and supporting market data
A12: NAVIGATION | E12: MODEL CONVENTIONS
A13: Dashboard | B13: =HYPERLINK("#'Dashboard'!A1","Open") -> Open | E13: Blue font | F13: Hardcoded inputs
A14: Financial Statements | B14: =HYPERLINK("#'Fin Statement'!A1","Open") -> Open | E14: Green font | F14: Cross-sheet formulas
A15: Common Size & Ratios | B15: =HYPERLINK("#'Common Size&Ratio'!A1","Open") -> Open | E15: Black font | F15: Same-sheet formulas / calculations
A16: Trend Analysis | B16: =HYPERLINK("#'Trend Analysis'!A1","Open") -> Open | E16: Red font | F16: External workbook links, if any
A17: Assumptions | B17: =HYPERLINK("#'Assumptions'!A1","Open") -> Open | E17: Units | F17: USD millions unless noted
A18: Three-Statement Model | B18: =HYPERLINK("#'3 statement Model'!A1","Open") -> Open | E18: Per-share values | F18: US dollars per diluted share
A19: DCF | B19: =HYPERLINK("#'DCF'!A1","Open") -> Open | E19: Historical periods | F19: FY2022–FY2026 actuals
A20: Valuation Sensitivities | B20: =HYPERLINK("#'Valuation Sensitivities'!A1","Open") -> Open | E20: Forecast periods | F20: FY2027–FY2031 estimates
A21: Trading Comps | B21: =HYPERLINK("#'Trading Comps'!A1","Open") -> Open | E21: Scenario selector | F21: Assumptions!L2; scenario name in Assumptions!M2
A22: WACC | B22: =HYPERLINK("#'WACC'!A1","Open") -> Open
A23: Beta / Supporting Market Data | B23: =HYPERLINK("#'Beta'!A1","Open") -> Open
A24: Sources & Definitions | B24: =HYPERLINK("#'Sources & Definitions'!A1","Open") -> Open
A27: MODEL STATUS & VALUATION REFERENCES | E27: PRINCIPAL SOURCES
A28: Active scenario | B28: =Assumptions!M2 -> Base | E28: Microsoft FY2026 Form 10-K | F28: Historical financial statements, leases, segments and disclosures
A29: Reference share price | B29: =DCF!E13 -> 531.33 | E29: Microsoft earnings materials | F29: Operating context and public company disclosures
A30: Active DCF value / share | B30: =DCF!E55 -> 403.26434 | E30: U.S. Treasury yield curve | F30: Risk-free rate; observation dated October 23, 2026
A31: WACC | B31: =DCF!E6 -> 0.090535584 | E31: Damodaran equity risk premium | F31: Market risk premium; observation dated October 1, 2026
A32: Terminal growth (active scenario) | B32: =DCF!E7 -> 0.025 | E32: MSFT market price / historical prices | F32: $531.33 close on October 27, 2026; Excel STOCKHISTORY for historical observations
A33: Terminal incremental ROIC (active scenario) | B33: =DCF!E9 -> 0.15 | E33: Peer company filings and dated market capitalizations | F33: Alphabet, Amazon, Oracle and Salesforce; conventions documented in Trading Comps
A34: Terminal value / enterprise value | B34: =DCF!E47 -> 0.69667511
A37: IMPORTANT DEFINITIONS
A38: Cash FCF | B38: Operating cash flow less cash additions to PP&E
A39: Economic UFCF | B39: Unlevered operating cash flow after economic reinvestment, including modeled lease-financed asset additions
A40: Net cash | B40: Cash plus short-term investments less conventional interest-bearing debt
A41: ROIC / incremental ROIC | B41: Consolidated return diagnostics; not direct measurements of AI-specific project returns
A44: DISCLAIMER
A45: This workbook contains independent financial research based on public information and explicitly stated analyst assumptions. Forecasts and valuations involve uncertainty. The material is not personalized investment advice or a recommendation to buy or sell securities.

Sheet Dashboard
A1: MICROSOFT CORPORATION — EQUITY RESEARCH DASHBOARD | M1: =HYPERLINK("#'Cover'!A1","Back to Cover") -> Back to Cover | P1: Year | Q1: Revenue ($bn) | R1: Operating income ($bn) | T1: Year | U1: Cash CapEx / revenue | V1: Economic investment / revenue | X1: Year | Y1: CFO ($bn) | Z1: Cash CapEx ($bn) | AA1: Cash FCF ($bn) | AC1: Valuation reference | AD1: Value / share
A2: NASDAQ: MSFT | Independent valuation and capital-productivity analysis | P2: ='Fin Statement'!E5 -> 2022A | Q2: ='3 statement Model'!E9/1000 -> 198.27 | R2: ='3 statement Model'!E25/1000 -> 83.383 | T2: ='Fin Statement'!E5 -> 2022A | U2: ='Common Size&Ratio'!E171 -> 0.12047208 | X2: ='Fin Statement'!E5 -> 2022A | Y2: ='3 statement Model'!E68/1000 -> 89.035 | Z2: =ABS('3 statement Model'!E76)/1000 -> 23.886 | AA2: ='Common Size&Ratio'!E168/1000 -> 65.149 | AC2: Market | AD2: =$B$9 -> 531.33
A3: Research question: Can Microsoft's AI investment generate sufficient returns to justify current capital intensity? | P3: ='Fin Statement'!F5 -> 2023A | Q3: ='3 statement Model'!F9/1000 -> 211.915 | R3: ='3 statement Model'!F25/1000 -> 88.523 | T3: ='Fin Statement'!F5 -> 2023A | U3: ='Common Size&Ratio'!F171 -> 0.13263337 | X3: ='Fin Statement'!F5 -> 2023A | Y3: ='3 statement Model'!F68/1000 -> 87.582 | Z3: =ABS('3 statement Model'!F76)/1000 -> 28.107 | AA3: ='Common Size&Ratio'!F168/1000 -> 59.475 | AC3: Bear DCF | AD3: 300.21849
P4: ='Fin Statement'!G5 -> 2024A | Q4: ='3 statement Model'!G9/1000 -> 245.122 | R4: ='3 statement Model'!G25/1000 -> 109.433 | T4: ='Fin Statement'!G5 -> 2024A | U4: ='Common Size&Ratio'!G171 -> 0.18144842 | X4: ='Fin Statement'!G5 -> 2024A | Y4: ='3 statement Model'!G68/1000 -> 118.548 | Z4: =ABS('3 statement Model'!G76)/1000 -> 44.477 | AA4: ='Common Size&Ratio'!G168/1000 -> 74.071 | AC4: Base DCF | AD4: 403.26434
A5: INVESTMENT OVERVIEW | P5: ='Fin Statement'!H5 -> 2025A | Q5: ='3 statement Model'!H9/1000 -> 281.724 | R5: ='3 statement Model'!H25/1000 -> 128.528 | T5: ='Fin Statement'!H5 -> 2025A | U5: ='Common Size&Ratio'!H171 -> 0.22912851 | X5: ='Fin Statement'!H5 -> 2025A | Y5: ='3 statement Model'!H68/1000 -> 136.162 | Z5: =ABS('3 statement Model'!H76)/1000 -> 64.551 | AA5: ='Common Size&Ratio'!H168/1000 -> 71.611 | AC5: Bull DCF | AD5: 500.32106
A6: Valuation reference date | B6: 46322 | D6: Research judgment | E6: Valuation-cautious / Unrated | H6: Active scenario | I6: =Assumptions!M2 -> Base | K6: Scenario selector | L6: =Assumptions!L2 -> 2 | P6: ='Fin Statement'!I5 -> 2026A | Q6: ='3 statement Model'!I9/1000 -> 331.839 | R6: ='3 statement Model'!I25/1000 -> 155.237 | T6: ='Fin Statement'!I5 -> 2026A | U6: ='Common Size&Ratio'!I171 -> 0.34941041 | X6: ='Fin Statement'!I5 -> 2026A | Y6: ='3 statement Model'!I68/1000 -> 182.935 | Z6: =ABS('3 statement Model'!I76)/1000 -> 115.948 | AA6: ='Common Size&Ratio'!I168/1000 -> 66.987 | AC6: Peer P/E | AD6: =$B$17 -> 506.60636
P7: ='Fin Statement'!J5 -> 2027E | Q7: ='3 statement Model'!J9/1000 -> 390.02904 | R7: ='3 statement Model'!J25/1000 -> 180.97347 | T7: ='Fin Statement'!J5 -> 2027E | U7: ='Common Size&Ratio'!J171 -> 0.35894763 | V7: ='Common Size&Ratio'!J205 -> 0.39740631 | X7: ='Fin Statement'!J5 -> 2027E | Y7: ='3 statement Model'!J68/1000 -> 222.14056 | Z7: =ABS('3 statement Model'!J76)/1000 -> 140 | AA7: ='Common Size&Ratio'!J168/1000 -> 82.140565
A8: VALUATION SUMMARY | P8: ='Fin Statement'!K5 -> 2028E | Q8: ='3 statement Model'!K9/1000 -> 460.28555 | R8: ='3 statement Model'!K25/1000 -> 214.49307 | T8: ='Fin Statement'!K5 -> 2028E | U8: ='Common Size&Ratio'!K171 -> 0.33674748 | V8: ='Common Size&Ratio'!K205 -> 0.36933595 | X8: ='Fin Statement'!K5 -> 2028E | Y8: ='3 statement Model'!K68/1000 -> 267.1957 | Z8: =ABS('3 statement Model'!K76)/1000 -> 155 | AA8: ='Common Size&Ratio'!K168/1000 -> 112.1957
A9: Reference share price | B9: =DCF!E13 -> 531.33 | D9: DATED, INDEPENDENTLY RECONCILED SCENARIO SNAPSHOTS | P9: ='Fin Statement'!L5 -> 2029E | Q9: ='3 statement Model'!L9/1000 -> 536.51482 | R9: ='3 statement Model'!L25/1000 -> 252.69848 | T9: ='Fin Statement'!L5 -> 2029E | U9: ='Common Size&Ratio'!L171 -> 0.31685984 | V9: ='Common Size&Ratio'!L205 -> 0.34481806 | X9: ='Fin Statement'!L5 -> 2029E | Y9: ='3 statement Model'!L68/1000 -> 317.1445 | Z9: =ABS('3 statement Model'!L76)/1000 -> 170 | AA9: ='Common Size&Ratio'!L168/1000 -> 147.1445
A10: Active-scenario DCF value | B10: =DCF!E55 -> 403.26434 | D10: Scenario | E10: DCF / share | F10: Upside / (downside) | P10: ='Fin Statement'!M5 -> 2030E | Q10: ='3 statement Model'!M9/1000 -> 618.2188 | R10: ='3 statement Model'!M25/1000 -> 293.65393 | T10: ='Fin Statement'!M5 -> 2030E | U10: ='Common Size&Ratio'!M171 -> 0.2992468 | V10: ='Common Size&Ratio'!M205 -> 0.32351006 | X10: ='Fin Statement'!M5 -> 2030E | Y10: ='3 statement Model'!M68/1000 -> 367.24669 | Z10: =ABS('3 statement Model'!M76)/1000 -> 185 | AA10: ='Common Size&Ratio'!M168/1000 -> 182.24669
A11: Active upside / (downside) | B11: =DCF!E57 -> -0.24102847 | D11: Bear | E11: 300.21849 | F11: =E11/$B$9-1 -> -0.43496793 | P11: ='Fin Statement'!N5 -> 2031E | Q11: ='3 statement Model'!N9/1000 -> 702.02722 | R11: ='3 statement Model'!N25/1000 -> 337.67509 | T11: ='Fin Statement'!N5 -> 2031E | U11: ='Common Size&Ratio'!N171 -> 0.28488924 | V11: ='Common Size&Ratio'!N205 -> 0.30625593 | X11: ='Fin Statement'!N5 -> 2031E | Y11: ='3 statement Model'!N68/1000 -> 423.39655 | Z11: =ABS('3 statement Model'!N76)/1000 -> 200 | AA11: ='Common Size&Ratio'!N168/1000 -> 223.39655
A12: WACC | B12: =DCF!E6 -> 0.090535584 | D12: Base | E12: 403.26434 | F12: =E12/$B$9-1 -> -0.24102847
A13: Terminal growth | B13: =DCF!E7 -> 0.025 | D13: Bull | E13: 500.32106 | F13: =E13/$B$9-1 -> -0.058360974
A14: Terminal incremental ROIC | B14: =DCF!E9 -> 0.15
A15: Terminal value / enterprise value | B15: =DCF!E47 -> 0.69667511 | D15: Snapshot basis | E15: Hardcoded scenario values are dated, independently reconciled snapshots.
A16: Peer P/E median | B16: ='Trading Comps'!P14 -> 28.126049 | D16: Snapshot date | E16: 46324
A17: Indicative peer P/E value | B17: ='Trading Comps'!F21 -> 506.60636 | D17: Method note | E17: Active DCF remains live-linked to the scenario selector.
A19: ="FINANCIAL PERFORMANCE — FY2026 ACTUAL VS FY2031 ACTIVE SCENARIO ("&UPPER(Assumptions!M2)&")" -> FINANCIAL PERFORMANCE — FY2026 ACTUAL VS FY2031 ACTIVE SCENARIO (BASE)
A20: Metric | B20: FY2026A | C20: ="FY2031E ("&Assumptions!M2&")" -> FY2031E (Base) | D20: Definition / unit
A21: Revenue | B21: ='3 statement Model'!I9 -> 331839 | C21: ='3 statement Model'!N9 -> 702027.22 | D21: USD millions
A22: Operating income | B22: ='3 statement Model'!I25 -> 155237 | C22: ='3 statement Model'!N25 -> 337675.09 | D22: USD millions
A23: Operating margin | B23: ='Common Size&Ratio'!I139 -> 0.46780818 | C23: ='Common Size&Ratio'!N139 -> 0.481 | D23: % of revenue
A24: Operating cash flow | B24: ='3 statement Model'!I68 -> 182935 | C24: ='3 statement Model'!N68 -> 423396.55 | D24: USD millions
A25: Cash CapEx | B25: =ABS('3 statement Model'!I76) -> 115948 | C25: =ABS('3 statement Model'!N76) -> 200000 | D25: Cash additions to PP&E; USD millions
A26: Economic CapEx | B26: n/a* | C26: ='3 statement Model'!N174+'3 statement Model'!N175 -> 215000 | D26: Cash PP&E + modeled lease-financed additions
A27: Cash FCF | B27: ='Common Size&Ratio'!I168 -> 66987 | C27: ='Common Size&Ratio'!N168 -> 223396.55 | D27: CFO less cash additions to PP&E
A28: Economic UFCF | B28: n/a* | C28: =DCF!I27 -> 181368.64 | D28: Unlevered cash flow after economic reinvestment
A29: Consolidated ROIC | B29: ='Common Size&Ratio'!I144 -> 0.3585794 | C29: ='Common Size&Ratio'!N144 -> 0.34983704 | D29: NOPAT / average invested capital
A30: Cash CapEx / revenue | B30: ='Common Size&Ratio'!I171 -> 0.34941041 | C30: ='Common Size&Ratio'!N171 -> 0.28488924 | D30: Cash additions to PP&E / revenue
A31: Economic investment / revenue | B31: n/a* | C31: ='Common Size&Ratio'!N205 -> 0.30625593 | D31: Forecast economic investment / revenue
A32: * Comparable historical lease additions and economic UFCF are unavailable; no unsupported FY2026 figure is inferred.
A34: MODEL STATUS — LIVE FORMULA CHECKS
A35: Balance sheet | B35: =IF(MAX(ABS('3 statement Model'!J127),ABS('3 statement Model'!K127),ABS('3 statement Model'!L127),ABS('3 statement Model'!M127),ABS('3 statement Model'!N127))<0.1,"PASS","FAIL") -> PASS | D35: Cash-flow / balance-sheet cash | E35: =IF(MAX(ABS('3 statement Model'!J84-'3 statement Model'!J91),ABS('3 statement Model'!K84-'3 statement Model'!K91),ABS('3 statement Model'!L84-'3 statement Model'!L91),ABS('3 statement Model'!M84-'3 statement Model'!M91),ABS('3 statement Model'!N84-'3 statement Model'!N91))<0.1,"PASS","FAIL") -> PASS | G35: PP&E roll-forward | H35: =IF(MAX(ABS('3 statement Model'!J185),ABS('3 statement Model'!K185),ABS('3 statement Model'!L185),ABS('3 statement Model'!M185),ABS('3 statement Model'!N185))<0.1,"PASS","FAIL") -> PASS | J35: Lease consistency | K35: =IF(MAX(ABS('3 statement Model'!J99-'3 statement Model'!J297),ABS('3 statement Model'!K99-'3 statement Model'!K297),ABS('3 statement Model'!L99-'3 statement Model'!L297),ABS('3 statement Model'!M99-'3 statement Model'!M297),ABS('3 statement Model'!N99-'3 statement Model'!N297),ABS('3 statement Model'!J117-'3 statement Model'!J301),ABS('3 statement Model'!K117-'3 statement Model'!K301),ABS('3 statement Model'!L117-'3 statement Model'!L301),ABS('3 statement Model'!M117-'3 statement Model'!M301),ABS('3 statement Model'!N117-'3 statement Model'!N301),ABS('3 statement Model'!J175-'3 statement Model'!J286),ABS('3 statement Model'!K175-'3 statement Model'!K286),ABS('3 statement Model'!L175-'3 statement Model'!L286),ABS('3 statement Model'!M175-'3 statement Model'!M286),ABS('3 statement Model'!N175-'3 statement Model'!N286),ABS('3 statement Model'!J73+'3 statement Model'!J292),ABS('3 statement Model'!K73+'3 statement Model'!K292),ABS('3 statement Model'!L73+'3 statement Model'!L292),ABS('3 statement Model'!M73+'3 statement Model'!M292),ABS('3 statement Model'!N73+'3 statement Model'!N292))<0.1,"PASS","FAIL") -> PASS | M35: Scenario / model | N35: ="ACTIVE: "&UPPER(Assumptions!M2)&" | CHECKS: "&IF(AND(B35="PASS",E35="PASS",H35="PASS",K35="PASS"),"PASS","REVIEW") -> ACTIVE: BASE | CHECKS: PASS
A37: INVESTMENT RISKS & INTERPRETIVE LIMITATIONS
A38: Utilization and monetization | B38: Returns depend on sustained demand, deployment utilization and monetization of the expanding AI infrastructure base.
A39: Margin sustainability | B39: High consolidated margins may not fully capture mix, pricing and depreciation pressure from accelerated infrastructure investment.
A40: Infrastructure replacement | B40: Short technology cycles may require replacement investment before modeled economic lives are exhausted.
A41: Capital intensity | B41: Cash CapEx remains elevated; FY2031 economic investment includes modeled finance-lease-financed asset additions.
A42: Terminal productivity | B42: Valuation is sensitive to terminal incremental ROIC and the large terminal-value contribution to enterprise value.
A43: AI-return limitation | B43: Company-wide ROIC and incremental ROIC are consolidated diagnostics, not direct measurements of AI-specific project returns.

Sheet Fin Statement
B1: Historical Financial Analysis: MSFT | N1: =HYPERLINK("#'Cover'!A1","Cover") -> Cover
F2: Year Ended June 30
B4: Income Statement | E4: Historical | I4: Forecasted
B5: (In millions, except per share amounts) | E5: =(2021+COLUMN()-COLUMN($D$5))&IF(COLUMN()-COLUMN($D$5)<5,"A","E") -> 2022A | F5: =(2021+COLUMN()-COLUMN($D$5))&IF(COLUMN()-COLUMN($D$5)<5,"A","E") -> 2023A | G5: =(2021+COLUMN()-COLUMN($D$5))&IF(COLUMN()-COLUMN($D$5)<5,"A","E") -> 2024A | H5: =(2021+COLUMN()-COLUMN($D$5))&IF(COLUMN()-COLUMN($D$5)<5,"A","E") -> 2025A | I5: 2026A | J5: =(2021+COLUMN()-COLUMN($D$5))&IF(COLUMN()-COLUMN($D$5)<5,"A","E") -> 2027E | K5: =(2021+COLUMN()-COLUMN($D$5))&IF(COLUMN()-COLUMN($D$5)<5,"A","E") -> 2028E | L5: =(2021+COLUMN()-COLUMN($D$5))&IF(COLUMN()-COLUMN($D$5)<5,"A","E") -> 2029E | M5: =(2021+COLUMN()-COLUMN($D$5))&IF(COLUMN()-COLUMN($D$5)<5,"A","E") -> 2030E | N5: =(2021+COLUMN()-COLUMN($D$5))&IF(COLUMN()-COLUMN($D$5)<5,"A","E") -> 2031E
B6: Revenue:
B7: Product | E7: 72732 | F7: 64699 | G7: 64773 | H7: 63946 | I7: 64696 | J7: ='3 statement Model'!J7 -> 65989.92 | K7: ='3 statement Model'!K7 -> 67309.718 | L7: ='3 statement Model'!L7 -> 68655.913 | M7: ='3 statement Model'!M7 -> 70029.031 | N7: ='3 statement Model'!N7 -> 71429.612
B8: Service and other | E8: 125538 | F8: 147216 | G8: 180349 | H8: 217778 | I8: 267143 | J8: ='3 statement Model'!J8 -> 324039.12 | K8: ='3 statement Model'!K8 -> 392975.83 | L8: ='3 statement Model'!L8 -> 467858.9 | M8: ='3 statement Model'!M8 -> 548189.77 | N8: ='3 statement Model'!N8 -> 630597.61
B9: Total revenue | E9: =SUM(E7:E8) -> 198270 | F9: =SUM(F7:F8) -> 211915 | G9: =SUM(G7:G8) -> 245122 | H9: =SUM(H7:H8) -> 281724 | I9: =SUM(I7:I8) -> 331839 | J9: =IF(COUNT(J7:J8)=0,"",SUM(J7:J8)) -> 390029.04 | K9: =IF(COUNT(K7:K8)=0,"",SUM(K7:K8)) -> 460285.55 | L9: =IF(COUNT(L7:L8)=0,"",SUM(L7:L8)) -> 536514.82 | M9: =IF(COUNT(M7:M8)=0,"",SUM(M7:M8)) -> 618218.8 | N9: =IF(COUNT(N7:N8)=0,"",SUM(N7:N8)) -> 702027.22
B10: COGS
B11: Product | E11: 19064 | F11: 17804 | G11: 15272 | H11: 13501 | I11: 12098 | J11: ='3 statement Model'!J12 -> 12339.96 | K11: ='3 statement Model'!K12 -> 12586.759 | L11: ='3 statement Model'!L12 -> 12838.494 | M11: ='3 statement Model'!M12 -> 13095.264 | N11: ='3 statement Model'!N12 -> 13357.17
B12: Service and other | E12: 43586 | F12: 48059 | G12: 58842 | H12: 74330 | I12: 94276 | J12: ='3 statement Model'!J13 -> 121830.03 | K12: ='3 statement Model'!K13 -> 145751.47 | L12: ='3 statement Model'!L13 -> 170649.57 | M12: ='3 statement Model'!M13 -> 197099.13 | N12: ='3 statement Model'!N13 -> 223928.03
B13: Total cost of revenue | E13: =SUM(E11:E12) -> 62650 | F13: =SUM(F11:F12) -> 65863 | G13: =SUM(G11:G12) -> 74114 | H13: =SUM(H11:H12) -> 87831 | I13: =SUM(I11:I12) -> 106374 | J13: =IF(COUNT(J11:J12)=0,"",SUM(J11:J12)) -> 134169.99 | K13: =IF(COUNT(K11:K12)=0,"",SUM(K11:K12)) -> 158338.23 | L13: =IF(COUNT(L11:L12)=0,"",SUM(L11:L12)) -> 183488.07 | M13: =IF(COUNT(M11:M12)=0,"",SUM(M11:M12)) -> 210194.39 | N13: =IF(COUNT(N11:N12)=0,"",SUM(N11:N12)) -> 237285.2
B15: Gross margin | E15: =E9-E13 -> 135620 | F15: =F9-F13 -> 146052 | G15: =G9-G13 -> 171008 | H15: =H9-H13 -> 193893 | I15: =I9-I13 -> 225465 | J15: =IF(OR(J9="",J13=""),"",J9-J13) -> 255859.05 | K15: =IF(OR(K9="",K13=""),"",K9-K13) -> 301947.32 | L15: =IF(OR(L9="",L13=""),"",L9-L13) -> 353026.75 | M15: =IF(OR(M9="",M13=""),"",M9-M13) -> 408024.41 | N15: =IF(OR(N9="",N13=""),"",N9-N13) -> 464742.02
B17: Research and development | E17: 24512 | F17: 27195 | G17: 29510 | H17: 32488 | I17: 35562 | J17: ='3 statement Model'!J18 -> 38612.875 | K17: ='3 statement Model'!K18 -> 45107.984 | L17: ='3 statement Model'!L18 -> 52041.937 | M17: ='3 statement Model'!M18 -> 59349.005 | N17: ='3 statement Model'!N18 -> 65990.559
B18: Sales and marketing | E18: 21825 | F18: 22759 | G18: 24456 | H18: 25654 | I18: 26710 | J18: ='3 statement Model'!J19 -> 28082.091 | K18: ='3 statement Model'!K19 -> 32680.274 | L18: ='3 statement Model'!L19 -> 37556.037 | M18: ='3 statement Model'!M19 -> 42657.097 | N18: ='3 statement Model'!N19 -> 47035.824
B19: General and administrative | E19: 5900 | F19: 7575 | G19: 7609 | H19: 7223 | I19: 7956 | J19: ='3 statement Model'!J20 -> 8190.6098 | K19: ='3 statement Model'!K20 -> 9665.9966 | L19: ='3 statement Model'!L20 -> 10730.296 | M19: ='3 statement Model'!M20 -> 12364.376 | N19: ='3 statement Model'!N20 -> 14040.544
B20: EBITDA | E20: =E22+E21 -> 97843 | F20: =F22+F21 -> 102384 | G20: =G22+G21 -> 130391 | H20: =H22+H21 -> 157961 | I20: =I22+I21 -> 193771 | J20: ='3 statement Model'!J21 -> 234680.35 | K20: ='3 statement Model'!K21 -> 281830.21 | L20: ='3 statement Model'!L21 -> 334436.74 | M20: ='3 statement Model'!M21 -> 389564.1 | N20: ='3 statement Model'!N21 -> 448271.99
B21: Depreciation, Amortization, and other | E21: =E57 -> 14460 | F21: =F57 -> 13861 | G21: =G57 -> 20958 | H21: =H57 -> 29433 | I21: =I57 -> 38534 | J21: ='3 statement Model'!J23 -> 53706.88 | K21: ='3 statement Model'!K23 -> 67337.146 | L21: ='3 statement Model'!L23 -> 81738.257 | M21: ='3 statement Model'!M23 -> 95910.173 | N21: ='3 statement Model'!N23 -> 110596.9
B22: Operating income/EBIT | E22: =E15-SUM(E17:E19) -> 83383 | F22: =F15-SUM(F17:F19) -> 88523 | G22: =G15-SUM(G17:G19) -> 109433 | H22: =H15-SUM(H17:H19) -> 128528 | I22: =I15-SUM(I17:I19) -> 155237 | J22: ='3 statement Model'!J25 -> 180973.47 | K22: ='3 statement Model'!K25 -> 214493.07 | L22: ='3 statement Model'!L25 -> 252698.48 | M22: ='3 statement Model'!M25 -> 293653.93 | N22: ='3 statement Model'!N25 -> 337675.09
B23: Interest and dividends income | E23: 2094 | F23: 2994 | G23: 3157 | H23: 2647 | I23: =IF(OR(H23="",G98="",H98="",I98=""),"",H23/AVERAGE(G98,H98)*AVERAGE(H98,I98)) -> 2789.8247 | J23: ='3 statement Model'!J26 -> 2689.505 | K23: ='3 statement Model'!K26 -> 3517.2654 | L23: ='3 statement Model'!L26 -> 5080.5689 | M23: ='3 statement Model'!M26 -> 7610.0667 | N23: ='3 statement Model'!N26 -> 10997.846
B24: Interest expense | E24: -2063 | F24: -1968 | G24: -2935 | H24: -2385 | I24: -3051 | J24: ='3 statement Model'!J27 -> -5169.0662 | K24: ='3 statement Model'!K27 -> -5446.6191 | L24: ='3 statement Model'!L27 -> -5712.7091 | M24: ='3 statement Model'!M27 -> -5965.1667 | N24: ='3 statement Model'!N27 -> -6171.5862
B25: Other non-operating items | E25: =E26-E23-E24 -> 302 | F25: =F26-F23-F24 -> -238 | G25: =G26-G23-G24 -> -1868 | H25: =H26-H23-H24 -> -5163 | I25: =IF(OR(I26="",I23="",I24=""),"",I26-I23-I24) -> 10958.175 | J25: =IF(OR(J26="",J23="",J24=""),"",J26-J23-J24) -> 0 | K25: =IF(OR(K26="",K23="",K24=""),"",K26-K23-K24) -> 0 | L25: =IF(OR(L26="",L23="",L24=""),"",L26-L23-L24) -> 0 | M25: =IF(OR(M26="",M23="",M24=""),"",M26-M23-M24) -> 0 | N25: =IF(OR(N26="",N23="",N24=""),"",N26-N23-N24) -> 0
B26: Other income (expense), net | E26: 333 | F26: 788 | G26: -1646 | H26: -4901 | I26: 10697 | J26: ='3 statement Model'!J29 -> -2479.5612 | K26: ='3 statement Model'!K29 -> -1929.3536 | L26: ='3 statement Model'!L29 -> -632.14019 | M26: ='3 statement Model'!M29 -> 1644.9 | N26: ='3 statement Model'!N29 -> 4826.2598
B27: EBT | E27: =E22+E26 -> 83716 | F27: =F22+F26 -> 89311 | G27: =G22+G26 -> 107787 | H27: =H22+H26 -> 123627 | I27: =I22+I26 -> 165934 | J27: ='3 statement Model'!J30 -> 178493.91 | K27: ='3 statement Model'!K30 -> 212563.71 | L27: ='3 statement Model'!L30 -> 252066.34 | M27: ='3 statement Model'!M30 -> 295298.83 | N27: ='3 statement Model'!N30 -> 342501.35
B28: Provision for income taxes/ Taxes | E28: 10978 | F28: 16950 | G28: 19651 | H28: 21795 | I28: 32185 | J28: ='3 statement Model'!J32 -> 35698.783 | K28: ='3 statement Model'!K32 -> 42512.743 | L28: ='3 statement Model'!L32 -> 50413.268 | M28: ='3 statement Model'!M32 -> 59059.766 | N28: ='3 statement Model'!N32 -> 68500.271
B29: Net income | E29: =E27-E28 -> 72738 | F29: =F27-F28 -> 72361 | G29: =G27-G28 -> 88136 | H29: =H27-H28 -> 101832 | I29: =I27-I28 -> 133749 | J29: ='3 statement Model'!J33 -> 142795.13 | K29: ='3 statement Model'!K33 -> 170050.97 | L29: ='3 statement Model'!L33 -> 201653.07 | M29: ='3 statement Model'!M33 -> 236239.06 | N29: ='3 statement Model'!N33 -> 274001.08
B32: Historical Reported / Forecast Analyst-Modeled Segment Results | E32: Historical | I32: Forecasted
B33: (In millions, except growth) | E33: =(2021+COLUMN()-COLUMN($D$5))&IF(COLUMN()-COLUMN($D$5)<5,"A","E") -> 2022A | F33: =(2021+COLUMN()-COLUMN($D$5))&IF(COLUMN()-COLUMN($D$5)<5,"A","E") -> 2023A | G33: =(2021+COLUMN()-COLUMN($D$5))&IF(COLUMN()-COLUMN($D$5)<5,"A","E") -> 2024A | H33: =(2021+COLUMN()-COLUMN($D$5))&IF(COLUMN()-COLUMN($D$5)<5,"A","E") -> 2025A | I33: 2026A | J33: =(2021+COLUMN()-COLUMN($D$5))&IF(COLUMN()-COLUMN($D$5)<5,"A","E") -> 2027E | K33: =(2021+COLUMN()-COLUMN($D$5))&IF(COLUMN()-COLUMN($D$5)<5,"A","E") -> 2028E | L33: =(2021+COLUMN()-COLUMN($D$5))&IF(COLUMN()-COLUMN($D$5)<5,"A","E") -> 2029E | M33: =(2021+COLUMN()-COLUMN($D$5))&IF(COLUMN()-COLUMN($D$5)<5,"A","E") -> 2030E | N33: =(2021+COLUMN()-COLUMN($D$5))&IF(COLUMN()-COLUMN($D$5)<5,"A","E") -> 2031E
B34: SEGMENT REVENUE
B35: Productivity and Business Processes | E35: 63364 | F35: 94151 | G35: 106820 | H35: 120810 | I35: 139996 | J35: ='3 statement Model'!J39 -> 156795.52 | K35: ='3 statement Model'!K39 -> 175610.98 | L35: ='3 statement Model'!L39 -> 194928.19 | M35: ='3 statement Model'!M39 -> 214421.01 | N35: ='3 statement Model'!N39 -> 233718.9
B36: Intelligent Cloud | E36: 74965 | F36: 72944 | G36: 87464 | H36: 106265 | I36: 137791 | J36: ='3 statement Model'!J40 -> 181884.12 | K36: ='3 statement Model'!K40 -> 232811.67 | L36: ='3 statement Model'!L40 -> 288686.48 | M36: ='3 statement Model'!M40 -> 349310.64 | N36: ='3 statement Model'!N40 -> 412186.55
B37: More Personal Computing | E37: 59941 | F37: 44820 | G37: 50838 | H37: 54649 | I37: 54052 | J37: ='3 statement Model'!J41 -> 51349.4 | K37: ='3 statement Model'!K41 -> 51862.894 | L37: ='3 statement Model'!L41 -> 52900.152 | M37: ='3 statement Model'!M41 -> 54487.156 | N37: ='3 statement Model'!N41 -> 56121.771
B38: Total segment revenue | E38: =SUM(E35:E37) -> 198270 | F38: =SUM(F35:F37) -> 211915 | G38: =SUM(G35:G37) -> 245122 | H38: =SUM(H35:H37) -> 281724 | I38: =SUM(I35:I37) -> 331839 | J38: =IF(COUNT(J35:J37)=0,"",SUM(J35:J37)) -> 390029.04 | K38: =IF(COUNT(K35:K37)=0,"",SUM(K35:K37)) -> 460285.55 | L38: =IF(COUNT(L35:L37)=0,"",SUM(L35:L37)) -> 536514.82 | M38: =IF(COUNT(M35:M37)=0,"",SUM(M35:M37)) -> 618218.8 | N38: =IF(COUNT(N35:N37)=0,"",SUM(N35:N37)) -> 702027.22
B40: SEGMENT OPERATING INCOME — FORECAST ANALYST ALLOCATION
B41: Productivity and Business Processes | E41: 29690 | F41: 50074 | G41: 59661 | H41: 69773 | I41: 83879 | J41: ='3 statement Model'!J45 -> 92998.559 | K41: ='3 statement Model'!K45 -> 104832.68 | L41: ='3 statement Model'!L45 -> 117942.27 | M41: ='3 statement Model'!M45 -> 131266.02 | N41: ='3 statement Model'!N45 -> 145317.77
B42: Intelligent Cloud | E42: 33203 | F42: 28411 | G42: 37813 | H42: 44589 | I42: 56972 | J42: ='3 statement Model'!J46 -> 74445.825 | K42: ='3 statement Model'!K46 -> 95907.544 | L42: ='3 statement Model'!L46 -> 120538.08 | M42: ='3 statement Model'!M46 -> 147570.58 | N42: ='3 statement Model'!N46 -> 176856.78
B43: More Personal Computing | E43: 20490 | F43: 10038 | G43: 11959 | H43: 14166 | I43: 14386 | J43: ='3 statement Model'!J47 -> 13529.091 | K43: ='3 statement Model'!K47 -> 13752.841 | L43: ='3 statement Model'!L47 -> 14218.128 | M43: ='3 statement Model'!M47 -> 14817.325 | N43: ='3 statement Model'!N47 -> 15500.544
B44: Total segment operating income | E44: =SUM(E41:E43) -> 83383 | F44: =SUM(F41:F43) -> 88523 | G44: =SUM(G41:G43) -> 109433 | H44: =SUM(H41:H43) -> 128528 | I44: =SUM(I41:I43) -> 155237 | J44: =IF(COUNT(J41:J43)=0,"",SUM(J41:J43)) -> 180973.47 | K44: =IF(COUNT(K41:K43)=0,"",SUM(K41:K43)) -> 214493.07 | L44: =IF(COUNT(L41:L43)=0,"",SUM(L41:L43)) -> 252698.48 | M44: =IF(COUNT(M41:M43)=0,"",SUM(M41:M43)) -> 293653.93 | N44: =IF(COUNT(N41:N43)=0,"",SUM(N41:N43)) -> 337675.09
B46: KEY CLOUD DISCLOSURE
B47: Azure revenue (minimum disclosed) | H47: >75,000
...

Sheet Common Size&Ratio
B1: Common-Size Financial Analysis: MSFT | N1: =HYPERLINK("#'Cover'!A1","Cover") -> Cover
F2: Year Ended June 30
B4: Income Statement | E4: Historical | I4: Forecasted
B5: (% of revenue) | E5: =(2021+COLUMN()-COLUMN($D$5))&IF(COLUMN()-COLUMN($D$5)<5,"A","E") -> 2022A | F5: =(2021+COLUMN()-COLUMN($D$5))&IF(COLUMN()-COLUMN($D$5)<5,"A","E") -> 2023A | G5: =(2021+COLUMN()-COLUMN($D$5))&IF(COLUMN()-COLUMN($D$5)<5,"A","E") -> 2024A | H5: =(2021+COLUMN()-COLUMN($D$5))&IF(COLUMN()-COLUMN($D$5)<5,"A","E") -> 2025A | I5: 2026A | J5: =(2021+COLUMN()-COLUMN($D$5))&IF(COLUMN()-COLUMN($D$5)<5,"A","E") -> 2027E | K5: =(2021+COLUMN()-COLUMN($D$5))&IF(COLUMN()-COLUMN($D$5)<5,"A","E") -> 2028E | L5: =(2021+COLUMN()-COLUMN($D$5))&IF(COLUMN()-COLUMN($D$5)<5,"A","E") -> 2029E | M5: =(2021+COLUMN()-COLUMN($D$5))&IF(COLUMN()-COLUMN($D$5)<5,"A","E") -> 2030E | N5: =(2021+COLUMN()-COLUMN($D$5))&IF(COLUMN()-COLUMN($D$5)<5,"A","E") -> 2031E
B6: Revenue:
B7: Product | E7: =IF('Fin Statement'!E7="","",'Fin Statement'!E7/'Fin Statement'!E9) -> 0.36683311 | F7: =IF('Fin Statement'!F7="","",'Fin Statement'!F7/'Fin Statement'!F9) -> 0.30530637 | G7: =IF('Fin Statement'!G7="","",'Fin Statement'!G7/'Fin Statement'!G9) -> 0.26424801 | H7: =IF('Fin Statement'!H7="","",'Fin Statement'!H7/'Fin Statement'!H9) -> 0.22698102 | I7: =IF('Fin Statement'!I7="","",'Fin Statement'!I7/'Fin Statement'!I9) -> 0.19496201 | J7: =IF('Fin Statement'!J7="","",'Fin Statement'!J7/'Fin Statement'!J9) -> 0.16919232 | K7: =IF('Fin Statement'!K7="","",'Fin Statement'!K7/'Fin Statement'!K9) -> 0.1462347 | L7: =IF('Fin Statement'!L7="","",'Fin Statement'!L7/'Fin Statement'!L9) -> 0.12796648 | ... N7: =IF('Fin Statement'!N7="","",'Fin Statement'!N7/'Fin Statement'!N9) -> 0.10174764
B8: Service and other | E8: =IF('Fin Statement'!E8="","",'Fin Statement'!E8/'Fin Statement'!E9) -> 0.63316689 | F8: =IF('Fin Statement'!F8="","",'Fin Statement'!F8/'Fin Statement'!F9) -> 0.69469363 | G8: =IF('Fin Statement'!G8="","",'Fin Statement'!G8/'Fin Statement'!G9) -> 0.73575199 | H8: =IF('Fin Statement'!H8="","",'Fin Statement'!H8/'Fin Statement'!H9) -> 0.77301898 | I8: =IF('Fin Statement'!I8="","",'Fin Statement'!I8/'Fin Statement'!I9) -> 0.80503799 | J8: =IF('Fin Statement'!J8="","",'Fin Statement'!J8/'Fin Statement'!J9) -> 0.83080768 | K8: =IF('Fin Statement'!K8="","",'Fin Statement'!K8/'Fin Statement'!K9) -> 0.8537653 | L8: =IF('Fin Statement'!L8="","",'Fin Statement'!L8/'Fin Statement'!L9) -> 0.87203352 | ... N8: =IF('Fin Statement'!N8="","",'Fin Statement'!N8/'Fin Statement'!N9) -> 0.89825236
B9: Total revenue | E9: =IF('Fin Statement'!E9="","",'Fin Statement'!E9/'Fin Statement'!E9) -> 1 | F9: =IF('Fin Statement'!F9="","",'Fin Statement'!F9/'Fin Statement'!F9) -> 1 | G9: =IF('Fin Statement'!G9="","",'Fin Statement'!G9/'Fin Statement'!G9) -> 1 | H9: =IF('Fin Statement'!H9="","",'Fin Statement'!H9/'Fin Statement'!H9) -> 1 | I9: =IF('Fin Statement'!I9="","",'Fin Statement'!I9/'Fin Statement'!I9) -> 1 | J9: =IF('Fin Statement'!J9="","",'Fin Statement'!J9/'Fin Statement'!J9) -> 1 | K9: =IF('Fin Statement'!K9="","",'Fin Statement'!K9/'Fin Statement'!K9) -> 1 | L9: =IF('Fin Statement'!L9="","",'Fin Statement'!L9/'Fin Statement'!L9) -> 1 | ... N9: =IF('Fin Statement'!N9="","",'Fin Statement'!N9/'Fin Statement'!N9) -> 1
B10: COGS
B11: Product | E11: =IF('Fin Statement'!E11="","",'Fin Statement'!E11/'Fin Statement'!E9) -> 0.096151712 | F11: =IF('Fin Statement'!F11="","",'Fin Statement'!F11/'Fin Statement'!F9) -> 0.084014817 | G11: =IF('Fin Statement'!G11="","",'Fin Statement'!G11/'Fin Statement'!G9) -> 0.062303669 | H11: =IF('Fin Statement'!H11="","",'Fin Statement'!H11/'Fin Statement'!H9) -> 0.04792279 | I11: =IF('Fin Statement'!I11="","",'Fin Statement'!I11/'Fin Statement'!I9) -> 0.036457439 | J11: =IF('Fin Statement'!J11="","",'Fin Statement'!J11/'Fin Statement'!J9) -> 0.031638567 | K11: =IF('Fin Statement'!K11="","",'Fin Statement'!K11/'Fin Statement'!K9) -> 0.027345545 | L11: =IF('Fin Statement'!L11="","",'Fin Statement'!L11/'Fin Statement'!L9) -> 0.023929431 | ... N11: =IF('Fin Statement'!N11="","",'Fin Statement'!N11/'Fin Statement'!N9) -> 0.019026569
B12: Service and other | E12: =IF('Fin Statement'!E12="","",'Fin Statement'!E12/'Fin Statement'!E9) -> 0.21983154 | F12: =IF('Fin Statement'!F12="","",'Fin Statement'!F12/'Fin Statement'!F9) -> 0.22678432 | G12: =IF('Fin Statement'!G12="","",'Fin Statement'!G12/'Fin Statement'!G9) -> 0.24005189 | H12: =IF('Fin Statement'!H12="","",'Fin Statement'!H12/'Fin Statement'!H9) -> 0.26383979 | I12: =IF('Fin Statement'!I12="","",'Fin Statement'!I12/'Fin Statement'!I9) -> 0.28410163 | J12: =IF('Fin Statement'!J12="","",'Fin Statement'!J12/'Fin Statement'!J9) -> 0.31236143 | K12: =IF('Fin Statement'!K12="","",'Fin Statement'!K12/'Fin Statement'!K9) -> 0.31665446 | L12: =IF('Fin Statement'!L12="","",'Fin Statement'!L12/'Fin Statement'!L9) -> 0.31807057 | ... N12: =IF('Fin Statement'!N12="","",'Fin Statement'!N12/'Fin Statement'!N9) -> 0.31897343
B13: Total cost of revenue | E13: =IF('Fin Statement'!E13="","",'Fin Statement'!E13/'Fin Statement'!E9) -> 0.31598326 | F13: =IF('Fin Statement'!F13="","",'Fin Statement'!F13/'Fin Statement'!F9) -> 0.31079914 | G13: =IF('Fin Statement'!G13="","",'Fin Statement'!G13/'Fin Statement'!G9) -> 0.30235556 | H13: =IF('Fin Statement'!H13="","",'Fin Statement'!H13/'Fin Statement'!H9) -> 0.31176258 | I13: =IF('Fin Statement'!I13="","",'Fin Statement'!I13/'Fin Statement'!I9) -> 0.32055907 | J13: =IF('Fin Statement'!J13="","",'Fin Statement'!J13/'Fin Statement'!J9) -> 0.344 | K13: =IF('Fin Statement'!K13="","",'Fin Statement'!K13/'Fin Statement'!K9) -> 0.344 | L13: =IF('Fin Statement'!L13="","",'Fin Statement'!L13/'Fin Statement'!L9) -> 0.342 | ... N13: =IF('Fin Statement'!N13="","",'Fin Statement'!N13/'Fin Statement'!N9) -> 0.338
B14: Gross margin | E14: =IF('Fin Statement'!E15="","",'Fin Statement'!E15/'Fin Statement'!E9) -> 0.68401674 | F14: =IF('Fin Statement'!F15="","",'Fin Statement'!F15/'Fin Statement'!F9) -> 0.68920086 | G14: =IF('Fin Statement'!G15="","",'Fin Statement'!G15/'Fin Statement'!G9) -> 0.69764444 | H14: =IF('Fin Statement'!H15="","",'Fin Statement'!H15/'Fin Statement'!H9) -> 0.68823742 | I14: =IF('Fin Statement'!I15="","",'Fin Statement'!I15/'Fin Statement'!I9) -> 0.67944093 | J14: =IF('Fin Statement'!J15="","",'Fin Statement'!J15/'Fin Statement'!J9) -> 0.656 | K14: =IF('Fin Statement'!K15="","",'Fin Statement'!K15/'Fin Statement'!K9) -> 0.656 | L14: =IF('Fin Statement'!L15="","",'Fin Statement'!L15/'Fin Statement'!L9) -> 0.658 | ... N14: =IF('Fin Statement'!N15="","",'Fin Statement'!N15/'Fin Statement'!N9) -> 0.662
B15: Research and development | E15: =IF('Fin Statement'!E17="","",'Fin Statement'!E17/'Fin Statement'!E9) -> 0.12362939 | F15: =IF('Fin Statement'!F17="","",'Fin Statement'!F17/'Fin Statement'!F9) -> 0.12832975 | G15: =IF('Fin Statement'!G17="","",'Fin Statement'!G17/'Fin Statement'!G9) -> 0.12038903 | H15: =IF('Fin Statement'!H17="","",'Fin Statement'!H17/'Fin Statement'!H9) -> 0.11531854 | I15: =IF('Fin Statement'!I17="","",'Fin Statement'!I17/'Fin Statement'!I9) -> 0.10716643 | J15: =IF('Fin Statement'!J17="","",'Fin Statement'!J17/'Fin Statement'!J9) -> 0.099 | K15: =IF('Fin Statement'!K17="","",'Fin Statement'!K17/'Fin Statement'!K9) -> 0.098 | L15: =IF('Fin Statement'!L17="","",'Fin Statement'!L17/'Fin Statement'!L9) -> 0.097 | ... N15: =IF('Fin Statement'!N17="","",'Fin Statement'!N17/'Fin Statement'!N9) -> 0.094
B16: Sales and marketing | E16: =IF('Fin Statement'!E18="","",'Fin Statement'!E18/'Fin Statement'!E9) -> 0.11007717 | F16: =IF('Fin Statement'!F18="","",'Fin Statement'!F18/'Fin Statement'!F9) -> 0.10739683 | G16: =IF('Fin Statement'!G18="","",'Fin Statement'!G18/'Fin Statement'!G9) -> 0.099770726 | H16: =IF('Fin Statement'!H18="","",'Fin Statement'!H18/'Fin Statement'!H9) -> 0.091060754 | I16: =IF('Fin Statement'!I18="","",'Fin Statement'!I18/'Fin Statement'!I9) -> 0.08049084 | J16: =IF('Fin Statement'!J18="","",'Fin Statement'!J18/'Fin Statement'!J9) -> 0.072 | K16: =IF('Fin Statement'!K18="","",'Fin Statement'!K18/'Fin Statement'!K9) -> 0.071 | L16: =IF('Fin Statement'!L18="","",'Fin Statement'!L18/'Fin Statement'!L9) -> 0.07 | ... N16: =IF('Fin Statement'!N18="","",'Fin Statement'!N18/'Fin Statement'!N9) -> 0.067
B17: General and administrative | E17: =IF('Fin Statement'!E19="","",'Fin Statement'!E19/'Fin Statement'!E9) -> 0.029757402 | F17: =IF('Fin Statement'!F19="","",'Fin Statement'!F19/'Fin Statement'!F9) -> 0.035745464 | G17: =IF('Fin Statement'!G19="","",'Fin Statement'!G19/'Fin Statement'!G9) -> 0.031041685 | H17: =IF('Fin Statement'!H19="","",'Fin Statement'!H19/'Fin Statement'!H9) -> 0.025638568 | I17: =IF('Fin Statement'!I19="","",'Fin Statement'!I19/'Fin Statement'!I9) -> 0.023975482 | J17: =IF('Fin Statement'!J19="","",'Fin Statement'!J19/'Fin Statement'!J9) -> 0.021 | K17: =IF('Fin Statement'!K19="","",'Fin Statement'!K19/'Fin Statement'!K9) -> 0.021 | L17: =IF('Fin Statement'!L19="","",'Fin Statement'!L19/'Fin Statement'!L9) -> 0.02 | ... N17: =IF('Fin Statement'!N19="","",'Fin Statement'!N19/'Fin Statement'!N9) -> 0.02
B18: EBITDA | E18: =IF('Fin Statement'!E20="","",'Fin Statement'!E20/'Fin Statement'!E9) -> 0.49348363 | F18: =IF('Fin Statement'!F20="","",'Fin Statement'!F20/'Fin Statement'!F9) -> 0.48313711 | G18: =IF('Fin Statement'!G20="","",'Fin Statement'!G20/'Fin Statement'!G9) -> 0.53194328 | H18: =IF('Fin Statement'!H20="","",'Fin Statement'!H20/'Fin Statement'!H9) -> 0.56069415 | I18: =IF('Fin Statement'!I20="","",'Fin Statement'!I20/'Fin Statement'!I9) -> 0.58393076 | J18: =IF('Fin Statement'!J20="","",'Fin Statement'!J20/'Fin Statement'!J9) -> 0.6016997 | K18: =IF('Fin Statement'!K20="","",'Fin Statement'!K20/'Fin Statement'!K9) -> 0.61229429 | L18: =IF('Fin Statement'!L20="","",'Fin Statement'!L20/'Fin Statement'!L9) -> 0.62335042 | ... N18: =IF('Fin Statement'!N20="","",'Fin Statement'!N20/'Fin Statement'!N9) -> 0.63853933
B19: Depreciation and Amortization | E19: =IF('Fin Statement'!E21="","",'Fin Statement'!E21/'Fin Statement'!E9) -> 0.072930852 | F19: =IF('Fin Statement'!F21="","",'Fin Statement'!F21/'Fin Statement'!F9) -> 0.0654083 | G19: =IF('Fin Statement'!G21="","",'Fin Statement'!G21/'Fin Statement'!G9) -> 0.085500281 | H19: =IF('Fin Statement'!H21="","",'Fin Statement'!H21/'Fin Statement'!H9) -> 0.10447459 | I19: =IF('Fin Statement'!I21="","",'Fin Statement'!I21/'Fin Statement'!I9) -> 0.11612258 | J19: =IF('Fin Statement'!J21="","",'Fin Statement'!J21/'Fin Statement'!J9) -> 0.1376997 | K19: =IF('Fin Statement'!K21="","",'Fin Statement'!K21/'Fin Statement'!K9) -> 0.14629429 | L19: =IF('Fin Statement'!L21="","",'Fin Statement'!L21/'Fin Statement'!L9) -> 0.15235042 | ... N19: =IF('Fin Statement'!N21="","",'Fin Statement'!N21/'Fin Statement'!N9) -> 0.15753933
B20: Operating income/EBIT | E20: =IF('Fin Statement'!E22="","",'Fin Statement'!E22/'Fin Statement'!E9) -> 0.42055278 | F20: =IF('Fin Statement'!F22="","",'Fin Statement'!F22/'Fin Statement'!F9) -> 0.41772881 | G20: =IF('Fin Statement'!G22="","",'Fin Statement'!G22/'Fin Statement'!G9) -> 0.446443 | H20: =IF('Fin Statement'!H22="","",'Fin Statement'!H22/'Fin Statement'!H9) -> 0.45621956 | I20: =IF('Fin Statement'!I22="","",'Fin Statement'!I22/'Fin Statement'!I9) -> 0.46780818 | J20: =IF('Fin Statement'!J22="","",'Fin Statement'!J22/'Fin Statement'!J9) -> 0.464 | K20: =IF('Fin Statement'!K22="","",'Fin Statement'!K22/'Fin Statement'!K9) -> 0.466 | L20: =IF('Fin Statement'!L22="","",'Fin Statement'!L22/'Fin Statement'!L9) -> 0.471 | ... N20: =IF('Fin Statement'!N22="","",'Fin Statement'!N22/'Fin Statement'!N9) -> 0.481
B21: Interest and dividends income | E21: =IFERROR('Fin Statement'!E23/'Fin Statement'!E9,"") -> 0.010561356 | F21: =IFERROR('Fin Statement'!F23/'Fin Statement'!F9,"") -> 0.014128306 | G21: =IFERROR('Fin Statement'!G23/'Fin Statement'!G9,"") -> 0.012879301 | H21: =IFERROR('Fin Statement'!H23/'Fin Statement'!H9,"") -> 0.0093957206 | I21: =IFERROR('Fin Statement'!I23/'Fin Statement'!I9,"") -> 0.0084071635 | J21: =IFERROR('Fin Statement'!J23/'Fin Statement'!J9,"") -> 0.0068956532 | K21: =IFERROR('Fin Statement'!K23/'Fin Statement'!K9,"") -> 0.0076414857 | L21: =IFERROR('Fin Statement'!L23/'Fin Statement'!L9,"") -> 0.0094695781 | ... N21: =IFERROR('Fin Statement'!N23/'Fin Statement'!N9,"") -> 0.01566584
B22: Interest expense | E22: =IFERROR('Fin Statement'!E24/'Fin Statement'!E9,"") -> -0.010405003 | F22: =IFERROR('Fin Statement'!F24/'Fin Statement'!F9,"") -> -0.0092867423 | G22: =IFERROR('Fin Statement'!G24/'Fin Statement'!G9,"") -> -0.011973629 | H22: =IFERROR('Fin Statement'!H24/'Fin Statement'!H9,"") -> -0.0084657324 | I22: =IFERROR('Fin Statement'!I24/'Fin Statement'!I9,"") -> -0.0091942177 | J22: =IFERROR('Fin Statement'!J24/'Fin Statement'!J9,"") -> -0.013253029 | K22: =IFERROR('Fin Statement'!K24/'Fin Statement'!K9,"") -> -0.011833131 | L22: =IFERROR('Fin Statement'!L24/'Fin Statement'!L9,"") -> -0.010647812 | ... N22: =IFERROR('Fin Statement'!N24/'Fin Statement'!N9,"") -> -0.0087910924
B23: Other non-operating items | E23: =IFERROR('Fin Statement'!E25/'Fin Statement'!E9,"") -> 0.0015231755 | F23: =IFERROR('Fin Statement'!F25/'Fin Statement'!F9,"") -> -0.0011230918 | G23: =IFERROR('Fin Statement'!G25/'Fin Statement'!G9,"") -> -0.007620695 | H23: =IFERROR('Fin Statement'!H25/'Fin Statement'!H9,"") -> -0.018326447 | I23: =IFERROR('Fin Statement'!I25/'Fin Statement'!I9,"") -> 0.033022566 | J23: =IFERROR('Fin Statement'!J25/'Fin Statement'!J9,"") -> 0 | K23: =IFERROR('Fin Statement'!K25/'Fin Statement'!K9,"") -> 0 | L23: =IFERROR('Fin Statement'!L25/'Fin Statement'!L9,"") -> 0 | ... N23: =IFERROR('Fin Statement'!N25/'Fin Statement'!N9,"") -> 0
B24: Other income (expense), net | E24: =IF('Fin Statement'!E26="","",'Fin Statement'!E26/'Fin Statement'!E9) -> 0.0016795279 | F24: =IF('Fin Statement'!F26="","",'Fin Statement'!F26/'Fin Statement'!F9) -> 0.003718472 | G24: =IF('Fin Statement'!G26="","",'Fin Statement'!G26/'Fin Statement'!G9) -> -0.0067150235 | H24: =IF('Fin Statement'!H26="","",'Fin Statement'!H26/'Fin Statement'!H9) -> -0.017396459 | I24: =IF('Fin Statement'!I26="","",'Fin Statement'!I26/'Fin Statement'!I9) -> 0.032235512 | J24: =IF('Fin Statement'!J26="","",'Fin Statement'!J26/'Fin Statement'!J9) -> -0.006357376 | K24: =IF('Fin Statement'!K26="","",'Fin Statement'!K26/'Fin Statement'!K9) -> -0.004191645 | L24: =IF('Fin Statement'!L26="","",'Fin Statement'!L26/'Fin Statement'!L9) -> -0.0011782344 | ... N24: =IF('Fin Statement'!N26="","",'Fin Statement'!N26/'Fin Statement'!N9) -> 0.0068747473
B25: EBT | E25: =IF('Fin Statement'!E27="","",'Fin Statement'!E27/'Fin Statement'!E9) -> 0.42223231 | F25: =IF('Fin Statement'!F27="","",'Fin Statement'!F27/'Fin Statement'!F9) -> 0.42144728 | G25: =IF('Fin Statement'!G27="","",'Fin Statement'!G27/'Fin Statement'!G9) -> 0.43972797 | H25: =IF('Fin Statement'!H27="","",'Fin Statement'!H27/'Fin Statement'!H9) -> 0.4388231 | I25: =IF('Fin Statement'!I27="","",'Fin Statement'!I27/'Fin Statement'!I9) -> 0.5000437 | J25: =IF('Fin Statement'!J27="","",'Fin Statement'!J27/'Fin Statement'!J9) -> 0.45764262 | K25: =IF('Fin Statement'!K27="","",'Fin Statement'!K27/'Fin Statement'!K9) -> 0.46180836 | L25: =IF('Fin Statement'!L27="","",'Fin Statement'!L27/'Fin Statement'!L9) -> 0.46982177 | ... N25: =IF('Fin Statement'!N27="","",'Fin Statement'!N27/'Fin Statement'!N9) -> 0.48787475
B26: Provision for income taxes/ Taxes | E26: =IF('Fin Statement'!E28="","",'Fin Statement'!E28/'Fin Statement'!E9) -> 0.055368941 | F26: =IF('Fin Statement'!F28="","",'Fin Statement'!F28/'Fin Statement'!F9) -> 0.0799849 | G26: =IF('Fin Statement'!G28="","",'Fin Statement'!G28/'Fin Statement'!G9) -> 0.080168243 | H26: =IF('Fin Statement'!H28="","",'Fin Statement'!H28/'Fin Statement'!H9) -> 0.077362951 | I26: =IF('Fin Statement'!I28="","",'Fin Statement'!I28/'Fin Statement'!I9) -> 0.096989805 | J26: =IF('Fin Statement'!J28="","",'Fin Statement'!J28/'Fin Statement'!J9) -> 0.091528525 | K26: =IF('Fin Statement'!K28="","",'Fin Statement'!K28/'Fin Statement'!K9) -> 0.092361671 | L26: =IF('Fin Statement'!L28="","",'Fin Statement'!L28/'Fin Statement'!L9) -> 0.093964353 | ... N26: =IF('Fin Statement'!N28="","",'Fin Statement'!N28/'Fin Statement'!N9) -> 0.097574949
B27: Net income | E27: =IF('Fin Statement'!E29="","",'Fin Statement'!E29/'Fin Statement'!E9) -> 0.36686337 | F27: =IF('Fin Statement'!F29="","",'Fin Statement'!F29/'Fin Statement'!F9) -> 0.34146238 | G27: =IF('Fin Statement'!G29="","",'Fin Statement'!G29/'Fin Statement'!G9) -> 0.35955973 | H27: =IF('Fin Statement'!H29="","",'Fin Statement'!H29/'Fin Statement'!H9) -> 0.36146015 | I27: =IF('Fin Statement'!I29="","",'Fin Statement'!I29/'Fin Statement'!I9) -> 0.40305389 | J27: =IF('Fin Statement'!J29="","",'Fin Statement'!J29/'Fin Statement'!J9) -> 0.3661141 | K27: =IF('Fin Statement'!K29="","",'Fin Statement'!K29/'Fin Statement'!K9) -> 0.36944668 | L27: =IF('Fin Statement'!L29="","",'Fin Statement'!L29/'Fin Statement'!L9) -> 0.37585741 | ... N27: =IF('Fin Statement'!N29="","",'Fin Statement'!N29/'Fin Statement'!N9) -> 0.3902998
B30: Reported Segment Results | E30: Historical | I30: Forecasted
B31: (% of segment total, except growth) | E31: =(2021+COLUMN()-COLUMN($D$5))&IF(COLUMN()-COLUMN($D$5)<5,"A","E") -> 2022A | F31: =(2021+COLUMN()-COLUMN($D$5))&IF(COLUMN()-COLUMN($D$5)<5,"A","E") -> 2023A | G31: =(2021+COLUMN()-COLUMN($D$5))&IF(COLUMN()-COLUMN($D$5)<5,"A","E") -> 2024A | H31: =(2021+COLUMN()-COLUMN($D$5))&IF(COLUMN()-COLUMN($D$5)<5,"A","E") -> 2025A | I31: 2026A | J31: =(2021+COLUMN()-COLUMN($D$5))&IF(COLUMN()-COLUMN($D$5)<5,"A","E") -> 2027E | K31: =(2021+COLUMN()-COLUMN($D$5))&IF(COLUMN()-COLUMN($D$5)<5,"A","E") -> 2028E | L31: =(2021+COLUMN()-COLUMN($D$5))&IF(COLUMN()-COLUMN($D$5)<5,"A","E") -> 2029E | M31: =(2021+COLUMN()-COLUMN($D$5))&IF(COLUMN()-COLUMN($D$5)<5,"A","E") -> 2030E | N31: =(2021+COLUMN()-COLUMN($D$5))&IF(COLUMN()-COLUMN($D$5)<5,"A","E") -> 2031E
B32: SEGMENT REVENUE
B33: Productivity and Business Processes | E33: =IF('Fin Statement'!E35="","",'Fin Statement'!E35/'Fin Statement'!E38) -> 0.31958441 | F33: =IF('Fin Statement'!F35="","",'Fin Statement'!F35/'Fin Statement'!F38) -> 0.44428662 | G33: =IF('Fin Statement'!G35="","",'Fin Statement'!G35/'Fin Statement'!G38) -> 0.435783 | H33: =IF('Fin Statement'!H35="","",'Fin Statement'!H35/'Fin Statement'!H38) -> 0.42882396 | I33: =IFERROR('Fin Statement'!I35/'Fin Statement'!I38,"") -> 0.42187928 | J33: =IF('Fin Statement'!J35="","",'Fin Statement'!J35/'Fin Statement'!J38) -> 0.40200986 | K33: =IF('Fin Statement'!K35="","",'Fin Statement'!K35/'Fin Statement'!K38) -> 0.38152617 | L33: =IF('Fin Statement'!L35="","",'Fin Statement'!L35/'Fin Statement'!L38) -> 0.36332303 | M33: =IF('Fin Statement'!M35="","",'Fin Statement'!M35/'Fin Statement'!M38) -> 0.34683677 | N33: =IF('Fin Statement'!N35="","",'Fin Statement'!N35/'Fin Statement'!N38) -> 0.33292
B34: Intelligent Cloud | E34: =IF('Fin Statement'!E36="","",'Fin Statement'!E36/'Fin Statement'!E38) -> 0.37809553 | F34: =IF('Fin Statement'!F36="","",'Fin Statement'!F36/'Fin Statement'!F38) -> 0.34421348 | G34: =IF('Fin Statement'!G36="","",'Fin Statement'!G36/'Fin Statement'!G38) -> 0.35681824 | H34: =IF('Fin Statement'!H36="","",'Fin Statement'!H36/'Fin Statement'!H38) -> 0.37719541 | I34: =IFERROR('Fin Statement'!I36/'Fin Statement'!I38,"") -> 0.4152345 | J34: =IF('Fin Statement'!J36="","",'Fin Statement'!J36/'Fin Statement'!J38) -> 0.46633481 | K34: =IF('Fin Statement'!K36="","",'Fin Statement'!K36/'Fin Statement'!K38) -> 0.50579835 | L34: =IF('Fin Statement'!L36="","",'Fin Statement'!L36/'Fin Statement'!L38) -> 0.53807736 | M34: =IF('Fin Statement'!M36="","",'Fin Statement'!M36/'Fin Statement'!M38) -> 0.56502752 | N34: =IF('Fin Statement'!N36="","",'Fin Statement'!N36/'Fin Statement'!N38) -> 0.58713756
B35: More Personal Computing | E35: =IF('Fin Statement'!E37="","",'Fin Statement'!E37/'Fin Statement'!E38) -> 0.30232007 | F35: =IF('Fin Statement'!F37="","",'Fin Statement'!F37/'Fin Statement'!F38) -> 0.21149989 | G35: =IF('Fin Statement'!G37="","",'Fin Statement'!G37/'Fin Statement'!G38) -> 0.20739876 | H35: =IF('Fin Statement'!H37="","",'Fin Statement'!H37/'Fin Statement'!H38) -> 0.19398063 | I35: =IFERROR('Fin Statement'!I37/'Fin Statement'!I38,"") -> 0.16288622 | J35: =IF('Fin Statement'!J37="","",'Fin Statement'!J37/'Fin Statement'!J38) -> 0.13165532 | K35: =IF('Fin Statement'!K37="","",'Fin Statement'!K37/'Fin Statement'!K38) -> 0.11267548 | L35: =IF('Fin Statement'!L37="","",'Fin Statement'!L37/'Fin Statement'!L38) -> 0.09859961 | M35: =IF('Fin Statement'!M37="","",'Fin Statement'!M37/'Fin Statement'!M38) -> 0.088135716 | N35: =IF('Fin Statement'!N37="","",'Fin Statement'!N37/'Fin Statement'!N38) -> 0.079942443
B36: Total segment revenue | E36: =IF('Fin Statement'!E38="","",'Fin Statement'!E38/'Fin Statement'!E38) -> 1 | F36: =IF('Fin Statement'!F38="","",'Fin Statement'!F38/'Fin Statement'!F38) -> 1 | G36: =IF('Fin Statement'!G38="","",'Fin Statement'!G38/'Fin Statement'!G38) -> 1 | H36: =IF('Fin Statement'!H38="","",'Fin Statement'!H38/'Fin Statement'!H38) -> 1 | I36: =IFERROR('Fin Statement'!I38/'Fin Statement'!I38,"") -> 1 | J36: =IF('Fin Statement'!J38="","",'Fin Statement'!J38/'Fin Statement'!J38) -> 1 | K36: =IF('Fin Statement'!K38="","",'Fin Statement'!K38/'Fin Statement'!K38) -> 1 | L36: =IF('Fin Statement'!L38="","",'Fin Statement'!L38/'Fin Statement'!L38) -> 1 | M36: =IF('Fin Statement'!M38="","",'Fin Statement'!M38/'Fin Statement'!M38) -> 1 | N36: =IF('Fin Statement'!N38="","",'Fin Statement'!N38/'Fin Statement'!N38) -> 1
B38: SEGMENT OPERATING INCOME
B39: Productivity and Business Processes | E39: =IF('Fin Statement'!E41="","",'Fin Statement'!E41/'Fin Statement'!E44) -> 0.35606778 | F39: =IF('Fin Statement'!F41="","",'Fin Statement'!F41/'Fin Statement'!F44) -> 0.5656609 | G39: =IF('Fin Statement'!G41="","",'Fin Statement'!G41/'Fin Statement'!G44) -> 0.5451829 | H39: =IF('Fin Statement'!H41="","",'Fin Statement'!H41/'Fin Statement'!H44) -> 0.54286226 | I39: =IFERROR('Fin Statement'!I41/'Fin Statement'!I44,"") -> 0.54032866 | J39: =IF('Fin Statement'!J41="","",'Fin Statement'!J41/'Fin Statement'!J44) -> 0.5138795 | K39: =IF('Fin Statement'!K41="","",'Fin Statement'!K41/'Fin Statement'!K44) -> 0.48874625 | L39: =IF('Fin Statement'!L41="","",'Fin Statement'!L41/'Fin Statement'!L44) -> 0.46673123 | M39: =IF('Fin Statement'!M41="","",'Fin Statement'!M41/'Fin Statement'!M44) -> 0.44700925 | N39: =IF('Fin Statement'!N41="","",'Fin Statement'!N41/'Fin Statement'!N44) -> 0.43034791
B40: Intelligent Cloud | E40: =IF('Fin Statement'!E42="","",'Fin Statement'!E42/'Fin Statement'!E44) -> 0.39819867 | F40: =IF('Fin Statement'!F42="","",'Fin Statement'!F42/'Fin Statement'!F44) -> 0.32094484 | G40: =IF('Fin Statement'!G42="","",'Fin Statement'!G42/'Fin Statement'!G44) -> 0.34553562 | H40: =IF('Fin Statement'!H42="","",'Fin Statement'!H42/'Fin Statement'!H44) -> 0.34692052 | I40: =IFERROR('Fin Statement'!I42/'Fin Statement'!I44,"") -> 0.36700014 | J40: =IF('Fin Statement'!J42="","",'Fin Statement'!J42/'Fin Statement'!J44) -> 0.41136319 | K40: =IF('Fin Statement'!K42="","",'Fin Statement'!K42/'Fin Statement'!K44) -> 0.44713587 | L40: =IF('Fin Statement'!L42="","",'Fin Statement'!L42/'Fin Statement'!L44) -> 0.47700358 | M40: =IF('Fin Statement'!M42="","",'Fin Statement'!M42/'Fin Statement'!M44) -> 0.50253229 | N40: =IF('Fin Statement'!N42="","",'Fin Statement'!N42/'Fin Statement'!N44) -> 0.52374836
B41: More Personal Computing | E41: =IF('Fin Statement'!E43="","",'Fin Statement'!E43/'Fin Statement'!E44) -> 0.24573354 | F41: =IF('Fin Statement'!F43="","",'Fin Statement'!F43/'Fin Statement'!F44) -> 0.11339426 | G41: =IF('Fin Statement'!G43="","",'Fin Statement'!G43/'Fin Statement'!G44) -> 0.10928148 | H41: =IF('Fin Statement'!H43="","",'Fin Statement'!H43/'Fin Statement'!H44) -> 0.11021723 | I41: =IFERROR('Fin Statement'!I43/'Fin Statement'!I44,"") -> 0.092671206 | J41: =IF('Fin Statement'!J43="","",'Fin Statement'!J43/'Fin Statement'!J44) -> 0.074757314 | K41: =IF('Fin Statement'!K43="","",'Fin Statement'!K43/'Fin Statement'!K44) -> 0.064117884 | L41: =IF('Fin Statement'!L43="","",'Fin Statement'!L43/'Fin Statement'!L44) -> 0.056265191 | M41: =IF('Fin Statement'!M43="","",'Fin Statement'!M43/'Fin Statement'!M44) -> 0.050458459 | N41: =IF('Fin Statement'!N43="","",'Fin Statement'!N43/'Fin Statement'!N44) -> 0.045903723
B42: Total segment operating income | E42: =IF('Fin Statement'!E44="","",'Fin Statement'!E44/'Fin Statement'!E44) -> 1 | F42: =IF('Fin Statement'!F44="","",'Fin Statement'!F44/'Fin Statement'!F44) -> 1 | G42: =IF('Fin Statement'!G44="","",'Fin Statement'!G44/'Fin Statement'!G44) -> 1 | H42: =IF('Fin Statement'!H44="","",'Fin Statement'!H44/'Fin Statement'!H44) -> 1 | I42: =IFERROR('Fin Statement'!I44/'Fin Statement'!I44,"") -> 1 | J42: =IF('Fin Statement'!J44="","",'Fin Statement'!J44/'Fin Statement'!J44) -> 1 | K42: =IF('Fin Statement'!K44="","",'Fin Statement'!K44/'Fin Statement'!K44) -> 1 | L42: =IF('Fin Statement'!L44="","",'Fin Statement'!L44/'Fin Statement'!L44) -> 1 | M42: =IF('Fin Statement'!M44="","",'Fin Statement'!M44/'Fin Statement'!M44) -> 1 | N42: =IF('Fin Statement'!N44="","",'Fin Statement'!N44/'Fin Statement'!N44) -> 1
B44: KEY CLOUD DISCLOSURE
B45: Azure revenue (minimum disclosed) | H45: >75,000
...

Sheet Trend Analysis
B1: Trend Analysis and Observation | P1: =HYPERLINK("#'Cover'!A1","Cover") -> Cover
E3: Historical | J3: Net Change | K3: Change per years | O3: Net Direction | P3: Pattern
B4: Profitability | E4: 2022 | F4: 2023 | G4: 2024 | H4: 2025 | I4: 2026 | J4: FY2022 - FY 2026 | K4: 2023 | L4: 2024 | M4: 2025 | N4: 2026
B5: Gross margin | E5: ='Common Size&Ratio'!E14 -> 0.68401674 | F5: ='Common Size&Ratio'!F14 -> 0.68920086 | G5: ='Common Size&Ratio'!G14 -> 0.69764444 | H5: ='Common Size&Ratio'!H14 -> 0.68823742 | I5: ='Common Size&Ratio'!I14 -> 0.67944093 | J5: =(I5-E5)*100 -> -0.45758111 | K5: =(F5-E5)*100 -> 0.5184114 | L5: =(G5-F5)*100 -> 0.84435794 | M5: =(H5-G5)*100 -> -0.94070144 | N5: =(I5-H5)*100 -> -0.87964902 | O5: =IF(J5>0,"Up",IF(J5<0,"Down","Flat")) -> Down | P5: {=IF(COUNT(K5:N5)<2,"n/a", IF(OR(COUNTIF(K5:N5,">0")=COUNT(K5:N5),COUNTIF(K5:N5,"<0")=COUNT(K5:N5)), IF(COUNTIF(K5:N5,">0")=COUNT(K5:N5),"Persistent rise – ","Persistent decline – ")& IF(ABS(N5)>1.25*SUMPRODUCT(ABS(IFERROR(K5:M5*1,0)))/COUNT(K5:M5),"accelerating", IF(ABS(N5)<0.75*SUMPRODUCT(ABS(IFERROR(K5:M5*1,0)))/COUNT(K5:M5),"decelerating","steady pace")), IF(SUMPRODUCT(--(IFERROR(K5:M5*L5:N5,0)<0))=1, IF(INDEX(K5:N5,MATCH(TRUE,INDEX(ISNUMBER(K5:N5),0),0))>0,"Reversing – peak ","Reversing – trough ")& INDEX($E$4:$I$4,MATCH(IF(INDEX(K5:N5,MATCH(TRUE,INDEX(ISNUMBER(K5:N5),0),0))>0,MAX(E5:I5),MIN(E5:I5)),E5:I5,0)), "Volatile – direction changed "&SUMPRODUCT(--(IFERROR(K5:M5*L5:N5,0)<0))&"x")))} -> Reversing – peak 2024
B6: EBIT (operating) margin | E6: ='Common Size&Ratio'!E20 -> 0.42055278 | F6: ='Common Size&Ratio'!F20 -> 0.41772881 | G6: ='Common Size&Ratio'!G20 -> 0.446443 | H6: ='Common Size&Ratio'!H20 -> 0.45621956 | I6: ='Common Size&Ratio'!I20 -> 0.46780818 | J6: =(I6-E6)*100 -> 4.7255403 | K6: =(F6-E6)*100 -> -0.28239752 | L6: =(G6-F6)*100 -> 2.8714189 | M6: =(H6-G6)*100 -> 0.97765667 | N6: =(I6-H6)*100 -> 1.1588622 | O6: =IF(J6>0,"Up",IF(J6<0,"Down","Flat")) -> Up | P6: {=IF(COUNT(K6:N6)<2,"n/a", IF(OR(COUNTIF(K6:N6,">0")=COUNT(K6:N6),COUNTIF(K6:N6,"<0")=COUNT(K6:N6)), IF(COUNTIF(K6:N6,">0")=COUNT(K6:N6),"Persistent rise – ","Persistent decline – ")& IF(ABS(N6)>1.25*SUMPRODUCT(ABS(IFERROR(K6:M6*1,0)))/COUNT(K6:M6),"accelerating", IF(ABS(N6)<0.75*SUMPRODUCT(ABS(IFERROR(K6:M6*1,0)))/COUNT(K6:M6),"decelerating","steady pace")), IF(SUMPRODUCT(--(IFERROR(K6:M6*L6:N6,0)<0))=1, IF(INDEX(K6:N6,MATCH(TRUE,INDEX(ISNUMBER(K6:N6),0),0))>0,"Reversing – peak ","Reversing – trough ")& INDEX($E$4:$I$4,MATCH(IF(INDEX(K6:N6,MATCH(TRUE,INDEX(ISNUMBER(K6:N6),0),0))>0,MAX(E6:I6),MIN(E6:I6)),E6:I6,0)), "Volatile – direction changed "&SUMPRODUCT(--(IFERROR(K6:M6*L6:N6,0)<0))&"x")))} -> Reversing – trough 2023
B7: Net profit margin | E7: ='Common Size&Ratio'!E27 -> 0.36686337 | F7: ='Common Size&Ratio'!F27 -> 0.34146238 | G7: ='Common Size&Ratio'!G27 -> 0.35955973 | H7: ='Common Size&Ratio'!H27 -> 0.36146015 | I7: ='Common Size&Ratio'!I27 -> 0.40305389 | J7: =(I7-E7)*100 -> 3.6190522 | K7: =(F7-E7)*100 -> -2.5400989 | L7: =(G7-F7)*100 -> 1.8097351 | M7: =(H7-G7)*100 -> 0.1900423 | N7: =(I7-H7)*100 -> 4.1593738 | O7: =IF(J7>0,"Up",IF(J7<0,"Down","Flat")) -> Up | P7: {=IF(COUNT(K7:N7)<2,"n/a", IF(OR(COUNTIF(K7:N7,">0")=COUNT(K7:N7),COUNTIF(K7:N7,"<0")=COUNT(K7:N7)), IF(COUNTIF(K7:N7,">0")=COUNT(K7:N7),"Persistent rise – ","Persistent decline – ")& IF(ABS(N7)>1.25*SUMPRODUCT(ABS(IFERROR(K7:M7*1,0)))/COUNT(K7:M7),"accelerating", IF(ABS(N7)<0.75*SUMPRODUCT(ABS(IFERROR(K7:M7*1,0)))/COUNT(K7:M7),"decelerating","steady pace")), IF(SUMPRODUCT(--(IFERROR(K7:M7*L7:N7,0)<0))=1, IF(INDEX(K7:N7,MATCH(TRUE,INDEX(ISNUMBER(K7:N7),0),0))>0,"Reversing – peak ","Reversing – trough ")& INDEX($E$4:$I$4,MATCH(IF(INDEX(K7:N7,MATCH(TRUE,INDEX(ISNUMBER(K7:N7),0),0))>0,MAX(E7:I7),MIN(E7:I7)),E7:I7,0)), "Volatile – direction changed "&SUMPRODUCT(--(IFERROR(K7:M7*L7:N7,0)<0))&"x")))} -> Reversing – trough 2023
B8: ROIC (NOPAT ÷ average invested capital) | E8: =IF('Common Size&Ratio'!E144="",0,"") -> 0 | F8: ='Common Size&Ratio'!F144 -> 0.56526971 | G8: ='Common Size&Ratio'!G144 -> 0.46272339 | H8: ='Common Size&Ratio'!H144 -> 0.39457044 | I8: ='Common Size&Ratio'!I144 -> 0.3585794 | J8: =(I8-E8)*100 -> 35.85794 | K8: =(F8-E8)*100 -> 56.526971 | L8: =(G8-F8)*100 -> -10.254632 | M8: =(H8-G8)*100 -> -6.8152949 | N8: =(I8-H8)*100 -> -3.5991046 | O8: =IF(J8>0,"Up",IF(J8<0,"Down","Flat")) -> Up | P8: {=IF(COUNT(K8:N8)<2,"n/a", IF(OR(COUNTIF(K8:N8,">0")=COUNT(K8:N8),COUNTIF(K8:N8,"<0")=COUNT(K8:N8)), IF(COUNTIF(K8:N8,">0")=COUNT(K8:N8),"Persistent rise – ","Persistent decline – ")& IF(ABS(N8)>1.25*SUMPRODUCT(ABS(IFERROR(K8:M8*1,0)))/COUNT(K8:M8),"accelerating", IF(ABS(N8)<0.75*SUMPRODUCT(ABS(IFERROR(K8:M8*1,0)))/COUNT(K8:M8),"decelerating","steady pace")), IF(SUMPRODUCT(--(IFERROR(K8:M8*L8:N8,0)<0))=1, IF(INDEX(K8:N8,MATCH(TRUE,INDEX(ISNUMBER(K8:N8),0),0))>0,"Reversing – peak ","Reversing – trough ")& INDEX($E$4:$I$4,MATCH(IF(INDEX(K8:N8,MATCH(TRUE,INDEX(ISNUMBER(K8:N8),0),0))>0,MAX(E8:I8),MIN(E8:I8)),E8:I8,0)), "Volatile – direction changed "&SUMPRODUCT(--(IFERROR(K8:M8*L8:N8,0)<0))&"x")))} -> Reversing – peak 2023
B9: ROCE (EBIT ÷ average capital employed) | E9: =IF('Common Size&Ratio'!E143="",,"0") -> 0 | F9: ='Common Size&Ratio'!F143 -> 0.30652804 | G9: ='Common Size&Ratio'!G143 -> 0.31504929 | H9: ='Common Size&Ratio'!H143 -> 0.29729073 | I9: ='Common Size&Ratio'!I143 -> 0.29088684 | J9: =(I9-E9)*100 -> 29.088684 | K9: =(F9-E9)*100 -> 30.652804 | L9: =(G9-F9)*100 -> 0.85212437 | M9: =(H9-G9)*100 -> -1.7758554 | N9: =(I9-H9)*100 -> -0.64038898 | O9: =IF(J9>0,"Up",IF(J9<0,"Down","Flat")) -> Up | P9: {=IF(COUNT(K9:N9)<2,"n/a", IF(OR(COUNTIF(K9:N9,">0")=COUNT(K9:N9),COUNTIF(K9:N9,"<0")=COUNT(K9:N9)), IF(COUNTIF(K9:N9,">0")=COUNT(K9:N9),"Persistent rise – ","Persistent decline – ")& IF(ABS(N9)>1.25*SUMPRODUCT(ABS(IFERROR(K9:M9*1,0)))/COUNT(K9:M9),"accelerating", IF(ABS(N9)<0.75*SUMPRODUCT(ABS(IFERROR(K9:M9*1,0)))/COUNT(K9:M9),"decelerating","steady pace")), IF(SUMPRODUCT(--(IFERROR(K9:M9*L9:N9,0)<0))=1, IF(INDEX(K9:N9,MATCH(TRUE,INDEX(ISNUMBER(K9:N9),0),0))>0,"Reversing – peak ","Reversing – trough ")& INDEX($E$4:$I$4,MATCH(IF(INDEX(K9:N9,MATCH(TRUE,INDEX(ISNUMBER(K9:N9),0),0))>0,MAX(E9:I9),MIN(E9:I9)),E9:I9,0)), "Volatile – direction changed "&SUMPRODUCT(--(IFERROR(K9:M9*L9:N9,0)<0))&"x")))} -> Reversing – peak 2024
